Workbook

Sheet Thuyết minh
A1: THUYẾT MINH CƠ SỞ XÂY DỰNG ĐỊNH MỨC
A2: MỨC THU DỊCH VỤ HỖ TRỢ HOẠT ĐỘNG GIÁO DỤC, ĐÀO TẠO ĐỐI VỚI CƠ SỞ GIÁO DỤC CÔNG LẬP TRÊN ĐỊA BÀN TỈNH TIỀN GIANG
A3: (Kèm theo Công văn số UBND- ngày tháng 7 năm 2023
A4: của Uỷ ban nhân dân tỉnh Tiền Giang)
A5: STT | B5: Nội dung | C5: Đơn vị tính | D5: Mức thu tối đa | E5: Thuyết minh cơ sở xây dựng định mức
A6: I | B6: MẦM NON
A7: 1 | B7: Hoạt động bán trú tại trường
A8: a | B8: Dịch vụ bán trú (chi trả lương nhân viên nấu ăn; hỗ trợ viên chức quản lý và giáo viên phục vụ bán trú; nhân viên kế toán, thủ quỹ phục vụ bán trú; phụ phí cho hoạt động bán trú: phục vụ vệ sinh đồ dùng, chế biến thức ăn, chất đốt, điện, nước sinh hoạt; khấu hao tài sản phục vụ bán trú).
B9: Hoạt động bán trú có tổ chức nấu ăn
B10: Chi trả lương nhân viên nấu ăn
B11: - Vùng II | C11: Đồng/tháng /học sinh | D11: 155000 | E11: Lương: 4.160.000 đồng, 7% người lao động có chứng chỉ nghề: 291.200 đồng, các khoản đóng góp (21,5%): 894.000 đồng, thâm niên: 1.302.000 đồng. Tổng cộng: 6.647.600 đồng. 6.647.600 đồng/ 45 HS = 147.724 đồng. Mức thu có tính thuế (147.724 đồng + 5% thuế)= 155.000 đồng
B12: - Vùng III | D12: 135000 | E12: Lương: 3.640.000 đồng, 7% người lao động có chứng chỉ nghề: 254.800 đồng, các khoản đóng góp (21,5%): 783.000 đồng, thâm niên: 1.134.000 đồng. Tổng cộng: 5.811.400 đồng. 5.811.400 đồng/ 45 HS = 129.142 đồng. Mức thu có tính thuế (129.142 đồng + 5% thuế)= 135.000 đồng.
B13: - Vùng IV | D13: 120000 | E13: Lương: 3.250.000 đồng, 7% người lao động có chứng chỉ nghề: 227.500 đồng, các khoản đóng góp (21,5%): 699.000 đồng, thâm niên: 1.008.000 đồng. Tổng cộng: 5.184.250 đồng. 5.184.250 đồng/ 45 HS = 115.206 đồng. Mức thu có tính thuế (115.206 đồng + 5% thuế)= 120.000 đồng.
B14: Chi hỗ trợ giáo viên phục vụ bán trú. | C14: Đồng/tháng /học sinh | D14: 88000 | E14: - Mức chi hỗ trợ trực 01 giờ trưa của 01 giáo viên: (3,0 x 1.800.000đ x 12 tháng) /(6 giờ x 5 ngày x 52 tuần) x 150% = 62.308 đ /giờ - Mức thu hỗ trợ 2 giờ trưa: (62.308đ x 2 giờ x 5 ngày x 4 tuần) /30 trẻ= 83.077đ/ tháng/trẻ. - Thuế: 83.077 đ x 5% = 4.154đ/tháng/trẻ Cộng số tiền: 83.077đ + 4.154đ = 87.231 đ/tháng/trẻ.
B15: Chi hỗ trợ viên chức quản lý, nhân viên kế toán, thủ quỹ phục vụ bán trú
B16: - Trường có quy mô từ 9 lớp trở lên | C16: Đồng/tháng /học sinh | D16: 17000 | E16: - Tiền lương làm thêm 01 giờ làm việc: (3,0 x 1.800.000đ) /22 ngày /8 giờ x 150% = 46.023đ - Số tiền chi hỗ trợ Viên chức quản lý, kế toán, thủ quỹ bán trú trong tháng: = (số tiền làm thêm 1 giờ x (số giờ làm thêm 1 ngày x 5 ngày làm việc/tuần x 4 tuần) + Viên chức quản lý: (46.023đ x 2 giờ x 5 ngày x 4 tuần x 2 người) = 3.681.818đ + Kế toán: (46.023đ x 2 giờ x 5 ngày x 4 tuần) = 1.840.909đ + Thủ quỹ: (46.023đ x 01 giờ x 5 ngày x 4 tuần) = 920.455đ - Số tiền 1 HS phải đóng: ( 3.681.818đ + 1.840.909đ + 920.455đ)/270 HS = 23.864đ - Thuế: 23.864đ x 5% = 1.193đ Cộng số tiền: 23.864đ + 1.193đ = 25.057 đ/tháng/trẻ.
B17: - Trường có quy mô từ 7 đến 8 lớp | D17: 20000
B18: - Trường có quy mô từ 6 lớp trở xuống | D18: 25000
B19: Phụ phí cho hoạt động bán trú (phục vụ vệ sinh đồ dùng, chế biến thức ăn, chất đốt, điện, nước sinh hoạt)
B20: - Trường thuộc địa bàn phường, thị trấn | C20: Đồng/tháng /học sinh | D20: 120000 | E20: Gồm các chất tẩy rửa vệ sinh phòng, vệ sinh đồ dùng cá nhân, đồ dùng chế biến thức ăn; chất đốt, điện, nước sinh hoạt phục vụ nấu ăn, sinh hoạt 4 giờ trưa. (có Bảng phụ lục danh mục sơ bộ đính kèm) Ước tính chi phí cho 01 lớp có 30 trẻ đăng ký ăn bán trú: 3.630.500 đồng / tháng - Số tiền: (Tổng mức chi phí/tháng/lớp)/30 trẻ = 3.630.500 đ /30 trẻ = 121.000đ - Thuế: 121.000đ x 5% = 6.050đ Cộng số tiền: 121.000đ + 6.050đ= 127.050đ đ/tháng/trẻ.
B21: - Trường thuộc địa bàn xã | D21: 100000
B22: Chi phí khấu hao tài sản phục vụ việc ăn uống | C22: Đồng/tháng /học sinh | D22: 26000 | E22: Chi phí khấu hao tài sản phục vụ ăn bán trú = chi phí khấu hao tài sản sử dụng cho hoạt động bán trú 01 tháng/ số trẻ Khấu hao tài sản 01 năm: 261.405.865 đồng. Khấu hao tài sản 01 giờ = 261.405.865 đồng /12 tháng / (8giờ x 22 ngày) = 123.772 đồng. - Khấu hao tài sản bình quân cho 01 HS/ tháng ăn trưa bán trú = 123.772 đồng /214 HS x 2 giờ x 22 ngày = 25.448đ - Thuế: 25.448đ x 5% = 1.272đ Cộng số tiền: 25.448đ + 1.272đ = 26.721đ/tháng/trẻ. Mức thu đề xuất: 26.000đ/tháng/trẻ.
B24: Hoạt động bán trú không tổ chức nấu ăn (nhà trường tổ chức giữ học sinh giờ bán trú, không tổ chức nấu ăn; nấu ăn do cơ sở dịch vụ nấu ăn cung cấp)
B25: Chi hỗ trợ giáo viên phục vụ bán trú. | C25: Đồng/tháng /học sinh | D25: 88000 | E25: - Mức chi hỗ trợ trực 01 giờ trưa của 01 giáo viên: (3,0 x 1.800.000đ x 12 tháng) /(6 giờ x 5 ngày x 52 tuần) x 150% = 62.308 đ /giờ - Mức thu hỗ trợ 2 giờ trưa: (62.308đ x 2 giờ x 5 ngày x 4 tuần) /30 trẻ= 83.077đ/ tháng/trẻ. - Thuế: 83.077 đ x 5% = 4.154đ/tháng/trẻ Cộng số tiền: 83.077đ + 4.154đ = 87.231 đ/tháng/trẻ.
B26: Chi hỗ trợ viên chức quản lý, nhân viên kế toán, thủ quỹ phục vụ bán trú | E26: Không tổ chức nấu ăn nhưng nhiệm vụ cũng giống như có tổ chức nấu ăn, chỉ giảm nhiệm vụ kiểm tra số lượng thực phẩm hàng ngày. Đề xuất thu bằng 80% đối với hoạt động có tổ chức nấu ăn. Tổ chức 6 lớp với 180 HS/4 đối tượng. Bình quân thu nhập 1 người/tháng là 280 HSx 18.400 =3.600/4 = 900.000 đ.
B27: Phụ phí cho hoạt động bán trú
B28: - Trường thuộc địa bàn phường, thị trấn | C28: Đồng/tháng /học sinh | D28: 70000 | E28: Gồm các chất tẩy rửa vệ sinh phòng, vệ sinh đồ dùng cá nhân, đồ dùng chế biến thức ăn; chất đốt, điện, nước sinh hoạt phục vụ nấu ăn, sinh hoạt 4 giờ trưa. (có Bảng phụ lục danh mục sơ bộ đính kèm) Ước tính chi phí cho 01 lớp có 30 trẻ đăng ký ăn bán trú: 3.630.500 đồng / tháng - Số tiền: (Tổng mức chi phí/tháng/lớp)/30 trẻ = 3.630.500 đ /30 trẻ = 68.000đ - Thuế:68.000đ x 5% = 3.400đ Cộng số tiền: 68.000đ + 3.400đ= 71.400đ đ/tháng/trẻ.
B29: - Trường thuộc địa bàn xã | D29: 50000
B30: Chi phí khấu hao tài sản phục vụ việc ăn uống | C30: Đồng/tháng /học sinh | D30: 20000 | E30: Chi phí khấu hao tài sản phục vụ ăn bán trú = chi phí khấu hao tài sản sử dụng cho hoạt động bán trú 01 tháng/ số trẻ Khấu hao tài sản 01 năm: 261.405.865 đồng. Khấu hao tài sản 01 giờ = 261.405.865 đồng /12 tháng / (8giờ x 22 ngày) = 100.195 đồng. - Khấu hao tài sản bình quân cho 01 HS/ tháng ăn trưa bán trú = 100.195 đồng /214 HS x 2 giờ x 22 ngày = 26.600đ - Thuế: 20.600đ x 5% = 1.030đ Cộng số tiền: 20.600đ + 1.030đ = 21.630đ/tháng/trẻ. Mức thu đề xuất: 20.000đ/tháng/trẻ. | F30: 211611500 | G30: =F30/12/8/22 -> 100194.84 | H30: =100195/214*2*22 -> 20600.841
A31: b | B31: Dịch vụ phục vụ tổ chức ăn sáng | C31: Đồng/bữa sáng/học sinh | D31: 5500 | E31: - Tiền công 1 giờ làm việc của 1 người: (3,0 x 1.800.000đ x 12 tháng) /(6 giờ x 5 ngày x 52 tuần) x 150% = 62.308 đ /giờ. Mức đóng của 1 HS: 62.308đ )/30 HS = 2.076 đồng/HS. - Phụ phí: 120.000 đồng/ HS/ tháng /22 ngày /2 giờ = 2.727 đồng/HS/ giờ - Khấu hao tài sản: 26.000 đồng/ HS/ tháng /22 ngày /2 giờ = 591 đồng/HS/ giờ - Thuế: =(2.076đ + 2.727đ +591đ)*5% = 270đ/ HS/ giờ Mức thu đề xuất: (2.076đ + 2.727đ +591đ + 270đ) = 5.664 đồng (làm tròn 5.500đ) | G31: =20600+1030 -> 21630 | H31: =20600*0.05 -> 1030
A32: 2 | B32: Dịch vụ giáo dục mầm non ngoài giờ
A33: a | B33: Chăm sóc, nuôi dưỡng, giáo dục trẻ em mầm non ngày thứ bảy, chủ nhật, ngày nghỉ lễ, tết. | C33: Đồng/ngày /học sinh | D33: 61000 | E33: - Tiền công 1 giờ làm việc của 1 người: (3,0 x 1.800.000đ x 12 tháng) /(6 giờ x 5 ngày x 52 tuần) x 150% = 62.308 đ /giờ - Mức đóng góp của 1 HS trả công tổ chức trông giữ trẻ: (02 người x 62.308đ x 10 giờ)/30 HS = 42.000 đồng/HS/ngày. - (Quản lý + Phụ phí + Khấu hao tài sản) =( 25.000/đồng +130.000đồng + 26.000 đồng) /20 ngày = 9.000 đồng/HS/ ngày - Thuế: = (42.000 + 9.000đ)*5% = 2.500đ/ HS/ ngày. -Tiền công nhân viên nấu ăn: 155.000 đồng/tháng/HS /20 ngày = 8.000 đồng Cộng số tiền : (42.000 + 9.000đ +2.500đ+ 8.000đ) = 61.500 đồng/ HS/ ngày Mức thu đề xuất: 61.000 đồng
A34: b | B34: Chăm sóc, nuôi dưỡng, giáo dục trẻ em mầm non ngày nghỉ hè | D34: 47000 | E34: - Tiền công 1 giờ làm việc của 1 người: (3,0 x 1.800.000đ x12 tháng) /(6 giờ x 5 ngày x 52 tuần) = 41.538 đ /giờ - Mức đóng góp của 1 HS trả công tổ chức trông giữ trẻ: (02 người x 41.538đ x 10 giờ)/30 HS = 28.000 đồng/HS/ngày. - (Quản lý + Phụ phí + Khấu hao tài sản) =( 25.000/đồng +120.000đồng + 26.000 đồng) /20 ngày = 9.000 đồng/HS/ ngày - Thuế: = (27.692đ + 8.550đ)*5% = 2.000đ/ HS/ ngày. - Tiền công nhân viên nấu ăn: 155.000 đồng/tháng/HS /20 ngày = 8.000 đồng Cộng số tiền : (28.000đ +9.000đ +2.000đ+ 8.000đ) = 47.000 đồng/ HS/ ngày
A35: 3 | B35: Dịch vụ hỗ trợ công tác vệ sinh lớp học
B36: - Vùng II | C36: Đồng/tháng /học sinh | D36: 20000 | E36: Lương vùng II: 4.160.000 đồng, các khoản đóng góp (21,5%): 894.000. Tổng cộng: 5.054.000 đồng. Tiền lương phải trả cho 01 nhân viên 01 giờ: 5.054.000/ (8 giờ x 22 ngày) = 29.000 đồng. Mức thu 01 trẻ/ tháng: (29.000 đồng x 5 ngày x 4 tuần) / 30 trẻ = 19.000 đồng. Mức thu có tính thuế (21.481 đồng + 5% thuế)= 20.000 đồng.
B37: - Vùng III | D37: 17000 | E37: Lương vùng III: 3.640.000 đồng, các khoản đóng góp (21,5%): 783.000 đồng. Tổng cộng: 4.423.000 đồng. Tiền lương phải trả cho 01 nhân viên 01 giờ: 4.423.000/ (8 giờ x 22 ngày) = 25.000 đồng. Mức thu 01 trẻ/ tháng: (25.000 đồng x 5 ngày x 4 tuần) / 30 trẻ = 16.000 đồng. Mức thu có tính thuế (16.000 đồng + 5% thuế)= 17.000 đồng.
B38: - Vùng IV | D38: 15000 | E38: Lương vùng IV: 3.250.000 đồng, các khoản đóng góp (21,5%): 699.000. Tổng cộng: 3.949.000 đồng. Tiền lương phải trả cho 01 nhân viên 01 giờ: 3.949.000/ (8 giờ x 22 ngày) = 22.000 đồng. Mức thu 01 trẻ/ tháng: (22.000 đồng x 5 ngày x 4 tuần) / 30 trẻ = 14.000 đồng. Mức thu có tính thuế (16.296 đồng + 5% thuế)= 15.000 đồng.
A39: II | B39: TIỂU HỌC
A40: 1 | B40: Hoạt động bán trú tại trường
A41: a | B41: Dịch vụ bán trú (chi trả lương nhân viên nấu ăn; hỗ trợ viên chức quản lý; hỗ trợ nhân viên phục vụ bán trú; nhân viên kế toán, thủ quỹ phục vụ bán trú; phụ phí cho hoạt động bán trú: phục vụ vệ sinh đồ dùng, chế biến thức ăn, chất đốt, điện, nước sinh hoạt; khấu hao tài sản phục vụ bán trú).
...

Sheet PhulucII
A1: Phụ lục II
A2: MỨC THU DỊCH VỤ PHỤC VỤ HOẠT ĐỘNG GIÁO DỤC, ĐÀO TẠO ĐỐI VỚI CƠ SỞ GIÁO DỤC CÔNG LẬP CHƯA TỰ BẢO ĐẢM CHI THƯỜNG XUYÊN TRÊN ĐỊA BÀN TỈNH TIỀN GIANG (Ban hành kèm theo Nghị quyết số 02/2025/NQ-HĐND ngày 29 tháng 4 năm 2025 của Hội đồng nhân dân tỉnh Tiền Giang)
A6: STT | B6: NỘI DUNG | C6: ĐƠN VỊ TÍNH | D6: MỨC THU
A7: I | B7: MẦM NON
A8: 1 | B8: Hoạt động bán trú tại trường
A9: a | B9: Dịch vụ bán trú (chi trả lương nhân viên nấu ăn; hỗ trợ viên chức quản lý và giáo viên phục vụ bán trú; nhân viên kế toán, thủ quỹ phục vụ bán trú; phụ phí cho hoạt động bán trú: phục vụ vệ sinh đồ dùng, chế biến thức ăn, chất đốt, điện, nước sinh hoạt; khấu hao tài sản phục vụ bán trú).
B10: Hoạt động bán trú có tổ chức nấu ăn
B11: - Chi trả lương nhân viên nấu ăn
B12: + Vùng II | C12: Đồng/tháng/ học sinh | D12: 155000
B13: + Vùng III | D13: 135000
B14: + Vùng IV | D14: 120000
B15: - Chi hỗ trợ giáo viên phục vụ bán trú. | C15: Đồng/tháng/ học sinh | D15: 88000
B16: - Chi hỗ trợ viên chức quản lý, nhân viên kế toán, thủ quỹ phục vụ bán trú
B17: + Trường có quy mô từ 9 lớp trở lên | C17: Đồng/tháng/ học sinh | D17: 17000
B18: + Trường có quy mô từ 7 đến 8 lớp | D18: 20000
B19: + Trường có quy mô từ 6 lớp trở xuống | D19: 25000
B20: - Phụ phí cho hoạt động bán trú (phục vụ vệ sinh đồ dùng, chế biến thức ăn, chất đốt, điện, nước sinh hoạt)
B21: + Trường thuộc địa bàn phường, thị trấn | C21: Đồng/tháng/ học sinh | D21: 120000
B22: + Trường thuộc địa bàn xã | D22: 100000
B23: - Chi phí khấu hao tài sản phục vụ việc ăn uống | C23: Đồng/tháng/ học sinh | D23: 26000
B24: TỔNG CỘNG
B25: - Trường thuộc địa bàn phường, thị trấn
B26: + Vùng II
B27: . Trường có quy mô từ 9 lớp trở lên | C27: Đồng/tháng/ học sinh | D27: 406000
B28: . Trường có quy mô từ 7 đến 8 lớp | D28: 409000
B29: . Trường có quy mô từ 6 lớp trở xuống | D29: 414000
B30: + Vùng III
B31: . Trường có quy mô từ 9 lớp trở lên | C31: Đồng/tháng/ học sinh | D31: 386000
B32: . Trường có quy mô từ 7 đến 8 lớp | D32: 389000
B33: . Trường có quy mô từ 6 lớp trở xuống | D33: 394000
B34: - Trường thuộc địa bàn xã
B35: + Vùng II
B36: . Trường có quy mô từ 9 lớp trở lên | C36: Đồng/tháng/ học sinh | D36: 386000
B37: . Trường có quy mô từ 7 đến 8 lớp | D37: 389000
B38: . Trường có quy mô từ 6 lớp trở xuống | D38: 394000
B39: + Vùng III
B40: . Trường có quy mô từ 9 lớp trở lên | C40: Đồng/tháng/ học sinh | D40: 366000
B41: . Trường có quy mô từ 7 đến 8 lớp | D41: 369000
B42: . Trường có quy mô từ 6 lớp trở xuống | D42: 374000
B43: + Vùng IV
...
