Workbook
Name bookmark50: 'Phụ lục 01'!#REF!
Name bookmark64: 'Phụ lục 01'!#REF!

Sheet foxz

Sheet Phụ lục 01
A1: Phụ lục I
A2: DANH MỤC NGHỀ ĐÀO TẠO TRÌNH ĐỘ SƠ CẤP, ĐÀO TẠO DƯỚI 3 THÁNG ÁP DỤNG TRONG LĨNH VỰC GIÁO DỤC NGHỀ NGHIỆP TRÊN ĐỊA BÀN TỈNH CÀ MAU
A3: (Ban hành kèm theo Quyết định số 85/2026/QĐ-UBND ngày 15 tháng 5 năm 2026 của Ủy ban nhân dân tỉnh Cà Mau)
A5: STT | B5: Nghề đào tạo | C5: Thời gian | E5: Trình độ
C6: Tổng số giờ dạy | D6: Thời gian tối thiểu hoàn thành khóa học (tháng/khóa)
A7: I | B7: Lĩnh vực nông nghiệp, chăn nuôi
A8: 1 | B8: Kỹ thuật trồng chuối xuất khẩu | C8: 480 | D8: 4 | E8: Sơ cấp
A9: 2 | B9: Kỹ thuật trồng hoa kiểng | C9: 120 | D9: 1.5 | E9: Dưới 03 tháng
A10: 3 | B10: Kỹ thuật trồng trọt (trồng cây ăn trái, trồng lúa, trồng rau màu, trồng nấm, sản xuất giống cây trồng, làm vườn,...) | C10: 160 | D10: 2 | E10: Dưới 03 tháng
A11: 4 | B11: Kỹ thuật chăn nuôi (chăn nuôi thú y, chăn nuôi gia súc an toàn sinh học, chăn nuôi gia cầm an toàn sinh học, chăn nuôi động vật hoang dã, chăn nuôi chồn, chăn nuôi heo, heo rừng….) | C11: 160 | D11: 2 | E11: Dưới 03 tháng
A12: II | B12: Lĩnh vực bảo vệ thực vật
A13: 1 | B13: Kỹ thuật viên bảo vệ thực vật | C13: 360 | D13: 4 | E13: Sơ cấp
A14: 2 | B14: Quản lý dịch hại tổng hợp | C14: 440 | D14: 4.5 | E14: Sơ cấp
A15: III | B15: Lĩnh vực lâm nghiệp
A16: 1 | B16: Kỹ thuật nuôi động vật hoang dã | C16: 300 | D16: 3 | E16: Sơ cấp
A17: 2 | B17: Kỹ thuật viên lâm nghiệp | C17: 120 | D17: 1.5 | E17: Dưới 03 tháng
A18: 3 | B18: Kỹ thuật trồng, khai thác rừng | C18: 120 | D18: 1.5 | E18: Dưới 03 tháng
A19: IV | B19: Lĩnh vực nuôi trồng thủy hải sản
A20: 1 | B20: Kỹ thuật nuôi trồng thủy sản nước ngọt | C20: 360 | D20: 4 | E20: Sơ cấp
A21: 2 | B21: Kỹ thuật nuôi trồng thủy sản nước lợ, mặn | C21: 360 | D21: 4 | E21: Sơ cấp
A22: 3 | B22: Kỹ thuật sản xuất giống thủy sản | C22: 300 | D22: 3 | E22: Sơ cấp
A23: 4 | B23: Kỹ thuật nuôi tôm ứng dụng công nghệ cao | C23: 304 | D23: 3 | E23: Sơ cấp
A24: 5 | B24: Kỹ thuật viên quản lý môi trường nuôi trồng thủy sản | C24: 304 | D24: 3 | E24: Sơ cấp
A25: 6 | B25: Kỹ thuật nuôi tôm càng xanh (nuôi thâm canh, bán thâm canh, quảng canh nhiều giai đoạn, nuôi kết hợp, nuôi trong ruộng lúa, nuôi theo hướng hữu cơ …) | C25: 160 | D25: 2 | E25: Dưới 03 tháng
A26: 7 | B26: Kỹ thuật nuôi tôm sú, kỹ thuật nuôi tôm thẻ (nuôi thâm canh, bán thâm canh, quảng canh nhiều giai đoạn, nuôi kết hợp, nuôi theo hướng hữu cơ,....) | C26: 160 | D26: 2 | E26: Dưới 03 tháng
A27: 8 | B27: Kỹ thuật nuôi cua (nuôi cua nhiều giai đoạn, nuôi cua quảng canh cải tiến, nuôi cua bán thâm canh, thâm canh, nuôi cua kết hợp, nuôi cua hai da, nuôi cua lột, nuôi cua theo hướng an toàn thực phẩm,...) | C27: 160 | D27: 2 | E27: Dưới 03 tháng
A28: 9 | B28: Kỹ thuật nuôi động vật thân mềm, hai mảnh vỏ (nuôi sò huyết, nuôi nghêu, hàu, ốc,...) | C28: 160 | D28: 2 | E28: Dưới 03 tháng
A29: 10 | B29: Kỹ thuật nuôi cá (cá chình, cá bống tượng, cá chạch, cá mú, cá chim,...) | C29: 120 | D29: 1.5 | E29: Dưới 03 tháng
A30: 11 | B30: Kỹ thuật nuôi hải sản (nuôi trong ao, lồng, bè,...) | C30: 120 | D30: 1.5 | E30: Dưới 03 tháng
A31: 12 | B31: Nuôi tôm, cua, cá kết hợp - lúa luân canh | C31: 240 | D31: 2 | E31: Dưới 03 tháng
A32: 13 | B32: Kỹ thuật nuôi lươn, nuôi ếch | C32: 120 | D32: 2 | E32: Dưới 03 tháng
A33: V | B33: Lĩnh vực khai thác thủy sản
A34: 1 | B34: Thuyền trưởng tàu cá hạng I | C34: 150 | D34: 1.5 | E34: Dưới 03 tháng
A35: 2 | B35: Máy trưởng tàu cá hạng I | C35: 150 | D35: 1.5 | E35: Dưới 03 tháng
A36: VI | B36: Lĩnh vực thủy lợi
A37: 1 | B37: Công nhân quản lý và khai thác công trình thủy lợi | C37: 352 | D37: 4 | E37: Sơ cấp
A38: VII | B38: Lĩnh vực hợp tác xã
A39: 1 | B39: Giám đốc hợp tác xã nông nghiệp | C39: 311 | D39: 3 | E39: Sơ cấp
A40: VIII | B40: Lĩnh vực kinh doanh, thương mại, dịch vụ
A41: 1 | B41: Hướng dẫn viên du lịch | C41: 320 | D41: 3 | E41: Sơ cấp
...

Sheet Phụ lục 2
A1: Phụ lục II
A2: MỨC HỖ TRỢ CHI PHÍ ĐÀO TẠO NGHỀ TRÌNH ĐỘ SƠ CẤP, ĐÀO TẠO DƯỚI 03 THÁNG ÁP DỤNG TRONG LĨNH VỰC GIÁO DỤC NGHỀ NGHIỆP TRÊN ĐỊA BÀN TỈNH CÀ MAU
A3: (Ban hành kèm theo Quyết định số 85/2026/QĐ-UBND ngày 15 tháng 5 năm 2026 của Ủy ban nhân dân tỉnh Cà Mau)
A5: STT | B5: Tên ngành nghề | C5: Thời gian | E5: Mức đào tạo đồng/người/khóa
C6: Tổng số giờ dạy | D6: Thời gian tối thiểu hoàn thành khóa học (tháng/khóa) | E6: Đối tượng 1 | F6: Đối tượng 2 | G6: Đối tượng 3 | H6: Đối tượng 4 | I6: Đối tượng 5
A7: I | B7: Lĩnh vực nông nghiệp, chăn nuôi
A8: 1 | B8: Kỹ thuật trồng chuối xuất khẩu | C8: ='Phụ lục 01'!C8 -> 480 | D8: ='Phụ lục 01'!D8 -> 4 | E8: 4800000 | F8: 3380000 | G8: 2535000 | H8: 2112500 | I8: 1690000
A9: 2 | B9: Kỹ thuật trồng hoa kiểng | C9: ='Phụ lục 01'!C9 -> 120 | D9: ='Phụ lục 01'!D9 -> 1.5 | E9: 4800000 | F9: 2514000 | G9: 1885500 | H9: 1571250 | I9: 1257000
A10: 3 | B10: Kỹ thuật trồng trọt (trồng cây ăn trái, trồng lúa, trồng rau màu, trồng nấm, sản xuất giống cây trồng, làm vườn,...) | C10: ='Phụ lục 01'!C10 -> 160 | D10: ='Phụ lục 01'!D10 -> 2 | E10: 4800000 | F10: 2760000 | G10: 2070000 | H10: 1725000 | I10: 1380000
A11: 4 | B11: Kỹ thuật chăn nuôi (chăn nuôi thú y, chăn nuôi gia súc an toàn sinh học, chăn nuôi gia cầm an toàn sinh học, chăn nuôi động vật hoang dã, chăn nuôi chồn, chăn nuôi heo, heo rừng....) | C11: ='Phụ lục 01'!C11 -> 160 | D11: ='Phụ lục 01'!D11 -> 2 | E11: 4800000 | F11: 3338000 | G11: 2503500 | H11: 2086250 | I11: 1669000
A12: II | B12: Lĩnh vực bảo vệ thực vật
A13: 1 | B13: Kỹ thuật viên bảo vệ thực vật | C13: ='Phụ lục 01'!C13 -> 360 | D13: ='Phụ lục 01'!D13 -> 4 | E13: 4800000 | F13: 3380000 | G13: 2535000 | H13: 2112500 | I13: 1690000
A14: 2 | B14: Quản lý dịch hại tổng hợp | C14: ='Phụ lục 01'!C14 -> 440 | D14: ='Phụ lục 01'!D14 -> 4.5 | E14: 4800000 | F14: 3380000 | G14: 2535000 | H14: 2112500 | I14: 1690000
A15: III | B15: Lĩnh vực lâm nghiệp
A16: 1 | B16: Kỹ thuật nuôi động vật hoang dã | C16: ='Phụ lục 01'!C16 -> 300 | D16: ='Phụ lục 01'!D16 -> 3 | E16: 4800000 | F16: 3160000 | G16: 2370000 | H16: 1975000 | I16: 1580000
A17: 2 | B17: Kỹ thuật viên lâm nghiệp | C17: ='Phụ lục 01'!C17 -> 120 | D17: ='Phụ lục 01'!D17 -> 1.5 | E17: 4800000 | F17: 2818000 | G17: 2113500 | H17: 1761250 | I17: 1409000
A18: 3 | B18: Kỹ thuật trồng, khai thác rừng | C18: ='Phụ lục 01'!C18 -> 120 | D18: ='Phụ lục 01'!D18 -> 1.5 | E18: 4800000 | F18: 1620000 | G18: 1215000 | H18: 1012500 | I18: 810000
A19: IV | B19: Lĩnh vực nuôi trồng thủy hải sản
A20: 1 | B20: Kỹ thuật nuôi trồng thủy sản nước ngọt | C20: ='Phụ lục 01'!C20 -> 360 | D20: ='Phụ lục 01'!D20 -> 4 | E20: 4800000 | F20: 3990000 | G20: 2992500 | H20: 2493750 | I20: 1995000
A21: 2 | B21: Kỹ thuật nuôi trồng thủy sản nước lợ, mặn | C21: ='Phụ lục 01'!C21 -> 360 | D21: ='Phụ lục 01'!D21 -> 4 | E21: 4800000 | F21: 3990000 | G21: 2992500 | H21: 2493750 | I21: 1995000
A22: 3 | B22: Kỹ thuật sản xuất giống thủy sản | C22: ='Phụ lục 01'!C22 -> 300 | D22: ='Phụ lục 01'!D22 -> 3 | E22: 4800000 | F22: 3990000 | G22: 2992500 | H22: 2493750 | I22: 1995000
A23: 4 | B23: Kỹ thuật nuôi tôm ứng dụng công nghệ cao | C23: ='Phụ lục 01'!C23 -> 304 | D23: ='Phụ lục 01'!D23 -> 3 | E23: 4800000 | F23: 4000000 | G23: 3000000 | H23: 2500000 | I23: 2000000
A24: 5 | B24: Kỹ thuật viên quản lý môi trường nuôi trồng thủy sản | C24: ='Phụ lục 01'!C24 -> 304 | D24: ='Phụ lục 01'!D24 -> 3 | E24: 4800000 | F24: 4000000 | G24: 3000000 | H24: 2500000 | I24: 2000000
A25: 6 | B25: Kỹ thuật nuôi tôm càng xanh (nuôi thâm canh, bán thâm canh, quảng canh nhiều giai đoạn, nuôi kết hợp, nuôi trong ruộng lúa, nuôi theo hướng hữu cơ …) | C25: ='Phụ lục 01'!C25 -> 160 | D25: ='Phụ lục 01'!D25 -> 2 | E25: 4800000 | F25: 3744000 | G25: 2808000 | H25: 2340000 | I25: 1872000
A26: 7 | B26: Kỹ thuật nuôi tôm sú, kỹ thuật nuôi tôm thẻ (nuôi thâm canh, bán thâm canh, quảng canh nhiều giai đoạn, nuôi kết hợp, nuôi theo hướng hữu cơ,....) | C26: ='Phụ lục 01'!C26 -> 160 | D26: ='Phụ lục 01'!D26 -> 2 | E26: 4800000 | F26: 3938000 | G26: 2953500 | H26: 2461250 | I26: 1969000
A27: 8 | B27: Kỹ thuật nuôi cua (nuôi cua nhiều giai đoạn, nuôi cua quảng canh cải tiến, nuôi cua bán thâm canh, thâm canh, nuôi cua kết hợp, nuôi cua hai da, nuôi cua lột, nuôi cua theo hướng an toàn thực phẩm,...) | C27: ='Phụ lục 01'!C27 -> 160 | D27: ='Phụ lục 01'!D27 -> 2 | E27: 4800000 | F27: 3938000 | G27: 2953500 | H27: 2461250 | I27: 1969000
A28: 9 | B28: Kỹ thuật nuôi động vật thân mềm, hai mảnh vỏ (nuôi sò huyết, nuôi nghêu, hàu, ốc,...) | C28: ='Phụ lục 01'!C28 -> 160 | D28: ='Phụ lục 01'!D28 -> 2 | E28: 4800000 | F28: 4000000 | G28: 3000000 | H28: 2500000 | I28: 2000000
A29: 10 | B29: Kỹ thuật nuôi cá (cá chình, cá bống tượng, cá chạch, cá mú, cá chim,...) | C29: ='Phụ lục 01'!C29 -> 120 | D29: ='Phụ lục 01'!D29 -> 1.5 | E29: 4800000 | F29: 3902000 | G29: 2926500 | H29: 2438750 | I29: 1951000
A30: 11 | B30: Kỹ thuật nuôi hải sản (nuôi trong ao, lồng, bè,...) | C30: ='Phụ lục 01'!C30 -> 120 | D30: ='Phụ lục 01'!D30 -> 1.5 | E30: 4800000 | F30: 3922000 | G30: 2941500 | H30: 2451250 | I30: 1961000
A31: 12 | B31: Nuôi tôm, cua, cá kết hợp - lúa luân canh | C31: ='Phụ lục 01'!C31 -> 240 | D31: ='Phụ lục 01'!D31 -> 2 | E31: 4800000 | F31: 4000000 | G31: 3000000 | H31: 2500000 | I31: 2000000
A32: 13 | B32: Kỹ thuật nuôi lươn, nuôi ếch | C32: 120 | D32: 2 | E32: 4800000 | F32: 3338000 | G32: 2503500 | H32: 2086250 | I32: 1869000
A33: V | B33: Lĩnh vực khai thác thủy sản
A34: 1 | B34: Thuyền trưởng tàu cá hạng I | C34: ='Phụ lục 01'!C34 -> 150 | D34: ='Phụ lục 01'!D34 -> 1.5 | F34: 4500000 | G34: 3000000 | H34: 2500000 | I34: 2000000
A35: 2 | B35: Máy trưởng tàu cá hạng I | C35: ='Phụ lục 01'!C35 -> 150 | D35: ='Phụ lục 01'!D35 -> 1.5 | F35: 4500000 | G35: 3000000 | H35: 2500000 | I35: 2000000
A36: VI | B36: Lĩnh vực thủy lợi
A37: 1 | B37: Công nhân quản lý và khai thác công trình thủy lợi | C37: ='Phụ lục 01'!C37 -> 352 | D37: ='Phụ lục 01'!D37 -> 4 | E37: 4800000 | F37: 4000000 | G37: 3000000 | H37: 2500000 | I37: 2000000
A38: VII | B38: Lĩnh vực hợp tác xã
A39: 1 | B39: Giám đốc hợp tác xã nông nghiệp | C39: ='Phụ lục 01'!C39 -> 311 | D39: ='Phụ lục 01'!D39 -> 3 | E39: 4800000 | F39: 4000000 | G39: 3000000 | H39: 2500000 | I39: 2000000
A40: VIII | B40: Lĩnh vực kinh doanh, thương mại, dịch vụ
A41: 1 | B41: Hướng dẫn viên du lịch | C41: ='Phụ lục 01'!C41 -> 320 | D41: ='Phụ lục 01'!D41 -> 3 | E41: 4800000 | F41: 3930000 | G41: 2947500 | H41: 2456250 | I41: 1965000
...
